<?xml version="1.0" ?>
<!-- =================================================================================== -->
<!-- |    This document was autogenerated by xacro from humarm_right.urdf.xacro        | -->
<!-- |    EDITING THIS FILE BY HAND IS NOT RECOMMENDED                                 | -->
<!-- =================================================================================== -->
<robot name="humarm_right">
  <!-- Material definitions -->
  <material name="blue">
    <color rgba="0.0 0.0 1.0 1.0"/>
  </material>
  <material name="red">
    <color rgba="1.0 0.0 0.0 1.0"/>
  </material>
  <material name="green">
    <color rgba="0.0 1.0 0.0 1.0"/>
  </material>
  <material name="yellow">
    <color rgba="1.0 1.0 0.0 1.0"/>
  </material>
  <material name="white">
    <color rgba="1.0 1.0 1.0 1.0"/>
  </material>
  <!-- World Link -->
  <link name="world"/>
  <!-- Fixed joint to connect robot to world -->
  <joint name="world_to_base" type="fixed">
    <parent link="world"/>
    <child link="base_link"/>
  </joint>
  <!-- Base Link (similar to torso_link in reference robot) -->
  <link name="base_link">
    <visual>
      <geometry>
        <box size="0.1 0.2 0.15"/>
      </geometry>
      <origin rpy="0 0 0" xyz="0 0 1.5"/>
      <material name="blue"/>
    </visual>
    <collision>
      <geometry>
        <box size="0.3 0.3 0.5"/>
      </geometry>
      <origin rpy="0 0 0" xyz="0 0 1.5"/>
    </collision>
    <inertial>
      <mass value="5.0"/>
      <origin rpy="0 0 0" xyz="0 0 0.25"/>
      <inertia ixx="0.15" ixy="0" ixz="0" iyy="0.15" iyz="0" izz="0.01"/>
    </inertial>
  </link>
  <!-- Shoulder Base Link (similar to right_shoul_base_link) -->
  <link name="right_shoulder_base_link">
    <visual>
      <geometry>
        <cylinder length="0.0125" radius="0.035"/>
      </geometry>
      <origin rpy="0 0 0" xyz="0 0 0.00625"/>
      <material name="white"/>
    </visual>
    <collision>
      <geometry>
        <cylinder length="0.0125" radius="0.122"/>
      </geometry>
      <origin rpy="0 0 0" xyz="0 0 0.00625"/>
    </collision>
    <inertial>
      <mass value="0.2"/>
      <origin rpy="0 0 0" xyz="0 0 0.00625"/>
      <inertia ixx="0.0000226" ixy="0" ixz="0" iyy="0.0000226" iyz="0" izz="0.00004"/>
    </inertial>
  </link>
  <!-- Joint connecting base to shoulder base (angled as in reference) -->
  <joint name="right_base_to_shoulder_base" type="fixed">
    <parent link="base_link"/>
    <child link="right_shoulder_base_link"/>
    <origin rpy="1.0472 0.436332 0" xyz="0 -0.1 1.5"/>
  </joint>
  <!-- 1. Shoulder Link (similar to right_shoul_link) -->
  <link name="right_shoulder_link">
    <visual>
      <geometry>
        <cylinder length="0.1465" radius="0.03"/>
      </geometry>
      <origin rpy="0 0 0" xyz="0 0 0.07325"/>
      <material name="red"/>
    </visual>
    <collision>
      <geometry>
        <cylinder length="0.1465" radius="0.03"/>
      </geometry>
      <origin rpy="0 0 0" xyz="0 0 0.07325"/>
    </collision>
    <inertial>
      <mass value="0.5"/>
      <origin rpy="0 0 0" xyz="0 0 0.07325"/>
      <inertia ixx="0.00015" ixy="0" ixz="0" iyy="0.00015" iyz="0" izz="0.00009"/>
    </inertial>
  </link>
  <!-- 1. Shoulder Pitch Joint (similar to right_shoul_base2shoul_joint) -->
  <joint name="right_shoulder_pitch" type="revolute">
    <parent link="right_shoulder_base_link"/>
    <child link="right_shoulder_link"/>
    <origin rpy="0 0 0" xyz="0 0 0.0125"/>
    <axis xyz="0 0 1"/>
    <limit effort="50" lower="-2.51" upper="2.51" velocity="15.0"/>
    <dynamics damping="0.5" friction="0.1"/>
  </joint>
  <!-- TRANSMISSION for shoulder_pitch -->
  <transmission name="trans_right_shoulder_pitch">
    <joint name="right_shoulder_pitch">
      <hardwareInterface>hardware_interface/PositionInterface</hardwareInterface>
    </joint>
    <actuator name="motor_a">
      <hardwareInterface>hardware_interface/PositionInterface</hardwareInterface>
      <mechanicalReduction>1</mechanicalReduction>
    </actuator>
  </transmission>
  <!-- 2. Upper Arm Link (similar to right_shoul_rot_link) -->
  <link name="right_upper_arm_link">
    <visual>
      <geometry>
        <cylinder length="0.05" radius="0.03"/>
      </geometry>
      <origin rpy="0 1.57075 0" xyz="0 0 0"/>
      <material name="blue"/>
    </visual>
    <collision>
      <geometry>
        <cylinder length="0.04" radius="0.03"/>
      </geometry>
      <origin rpy="0 1.57075 0" xyz="0 0 0"/>
    </collision>
    <inertial>
      <mass value="0.2"/>
      <origin rpy="0 0 0" xyz="0 0 0"/>
      <inertia ixx="0.00007" ixy="0" ixz="0" iyy="0.00007" iyz="0" izz="0.00009"/>
    </inertial>
  </link>
  <!-- 2. Shoulder Roll Joint (similar to right_shoul2shoul_rot_joint) -->
  <joint name="right_shoulder_roll" type="revolute">
    <parent link="right_shoulder_link"/>
    <child link="right_upper_arm_link"/>
    <origin rpy="-1.0472 -0.436332 0" xyz="0 0 0.1465"/>
    <axis xyz="1 0 0"/>
    <limit effort="50" lower="-1.57" upper="0.50" velocity="15.0"/>
    <dynamics damping="0.5" friction="0.1"/>
  </joint>
  <!-- TRANSMISSION for shoulder_roll -->
  <transmission name="trans_right_shoulder_roll">
    <joint name="right_shoulder_roll">
      <hardwareInterface>hardware_interface/PositionInterface</hardwareInterface>
    </joint>
    <actuator name="motor_b">
      <hardwareInterface>hardware_interface/PositionInterface</hardwareInterface>
      <mechanicalReduction>1</mechanicalReduction>
    </actuator>
  </transmission>
  <!-- Upper Arm Extension Link (similar to right_upper_arm_link) -->
  <link name="right_upper_arm_extension_link">
    <visual>
      <geometry>
        <cylinder length="0.1755" radius="0.03"/>
      </geometry>
      <origin rpy="0 0 0" xyz="0 0 -0.08775"/>
      <material name="white"/>
    </visual>
    <collision>
      <geometry>
        <cylinder length="0.1755" radius="0.03"/>
      </geometry>
      <origin rpy="0 0 0" xyz="0 0 -0.08775"/>
    </collision>
    <inertial>
      <mass value="0.1"/>
      <origin rpy="0 0 0" xyz="0 0 -0.08775"/>
      <inertia ixx="0.000279" ixy="0" ixz="0" iyy="0.000279" iyz="0" izz="0.000045"/>
      <!-- Recalculated -->
    </inertial>
  </link>
  <!-- Fixed joint connecting upper_arm_link to extension -->
  <joint name="right_upper_arm_to_extension" type="fixed">
    <parent link="right_upper_arm_link"/>
    <child link="right_upper_arm_extension_link"/>
    <origin rpy="0 0 0" xyz="0 0 0"/>
  </joint>
  <!-- 3. Upper Arm Rotation Link (similar to right_armrot_link) -->
  <link name="right_upper_arm_rotation_link">
    <visual>
      <geometry>
        <cylinder length="0.1755" radius="0.03"/>
      </geometry>
      <origin rpy="0 0 0" xyz="0 0 -0.08775"/>
      <material name="green"/>
    </visual>
    <collision>
      <geometry>
        <cylinder length="0.1755" radius="0.03"/>
      </geometry>
      <origin rpy="0 0 0" xyz="0 0 -0.08775"/>
    </collision>
    <inertial>
      <mass value="0.8"/>
      <origin rpy="0 0 0" xyz="0 0 -0.08775"/>
      <inertia ixx="0.002233" ixy="0" ixz="0" iyy="0.002233" iyz="0" izz="0.00036"/>
      <!-- Recalculated -->
    </inertial>
  </link>
  <!-- 3. Upper Arm Rotation Joint (similar to right_arm2armrot_joint) -->
  <joint name="right_upper_arm_rotation" type="revolute">
    <parent link="right_upper_arm_extension_link"/>
    <child link="right_upper_arm_rotation_link"/>
    <origin rpy="0 0 0" xyz="0 0 -0.1755"/>
    <axis xyz="0 0 1"/>
    <limit effort="50" lower="-1.57" upper="1.57" velocity="15.0"/>
    <dynamics damping="0.1" friction="0.1"/>
  </joint>
  <!-- TRANSMISSION for upper_arm_rotation -->
  <transmission name="right_rans_upper_arm_rotation">
    <joint name="right_upper_arm_rotation">
      <hardwareInterface>hardware_interface/PositionInterface</hardwareInterface>
    </joint>
    <actuator name="motor_c">
      <hardwareInterface>hardware_interface/PositionInterface</hardwareInterface>
      <mechanicalReduction>1</mechanicalReduction>
    </actuator>
  </transmission>
  <!-- 4. Elbow Link (similar to right_elbow_link) -->
  <link name="right_elbow_link">
    <visual>
      <geometry>
        <cylinder length="0.05" radius="0.03"/>
      </geometry>
      <origin rpy="1.57075 0 0" xyz="0 0 0"/>
      <material name="blue"/>
    </visual>
    <collision>
      <geometry>
        <cylinder length="0.08" radius="0.03"/>
      </geometry>
      <origin rpy="1.57075 0 0" xyz="0 0 0"/>
    </collision>
    <inertial>
      <mass value="0.5"/>
      <origin rpy="0 0 0" xyz="0 0 0"/>
      <inertia ixx="0.0005" ixy="0" ixz="0" iyy="0.0005" iyz="0" izz="0.0005"/>
    </inertial>
  </link>
  <!-- 4. Elbow Pitch Joint (similar to right_armrot2elbow_joint) -->
  <joint name="right_elbow_pitch" type="revolute">
    <parent link="right_upper_arm_rotation_link"/>
    <child link="right_elbow_link"/>
    <origin rpy="0 0 0" xyz="0 0 -0.1755"/>
    <axis xyz="0 1 0"/>
    <limit effort="50" lower="-2.2" upper="0" velocity="15.0"/>
    <dynamics damping="0.1" friction="0.1"/>
  </joint>
  <!-- TRANSMISSION for elbow_pitch -->
  <transmission name="right_trans_elbow_pitch">
    <joint name="right_elbow_pitch">
      <hardwareInterface>hardware_interface/PositionInterface</hardwareInterface>
    </joint>
    <actuator name="motor_d">
      <hardwareInterface>hardware_interface/PositionInterface</hardwareInterface>
      <mechanicalReduction>1</mechanicalReduction>
    </actuator>
  </transmission>
  <!-- 5. Forearm Link (similar to right_forearm_link) -->
  <link name="right_forearm_link">
    <visual>
      <geometry>
        <cylinder length="0.104" radius="0.025"/>
      </geometry>
      <origin rpy="0 0 0" xyz="0 0 -0.052"/>
      <material name="white"/>
    </visual>
    <collision>
      <geometry>
        <cylinder length="0.104" radius="0.025"/>
      </geometry>
      <origin rpy="0 0 0" xyz="0 0 -0.052"/>
    </collision>
    <inertial>
      <mass value="0.15"/>
      <origin rpy="0 0 0" xyz="0 0 -0.052"/>
      <inertia ixx="0.000169" ixy="0" ixz="0" iyy="0.000169" iyz="0" izz="0.0000675"/>
    </inertial>
  </link>
  <!-- Fixed joint connecting elbow to forearm -->
  <joint name="right_elbow_forearm_connection" type="fixed">
    <parent link="right_elbow_link"/>
    <child link="right_forearm_link"/>
    <origin rpy="0 0 0" xyz="0 0 0"/>
  </joint>
  <!-- 5. Forearm Rotation Link (similar to right_forearmrot_link) -->
  <link name="right_forearm_rotation_link">
    <visual>
      <geometry>
        <cylinder length="0.104" radius="0.025"/>
      </geometry>
      <origin rpy="0 0 0" xyz="0 0 -0.052"/>
      <material name="yellow"/>
    </visual>
    <collision>
      <geometry>
        <cylinder length="0.104" radius="0.025"/>
      </geometry>
      <origin rpy="0 0 0" xyz="0 0 -0.052"/>
    </collision>
    <inertial>
      <mass value="0.5"/>
      <origin rpy="0 0 0" xyz="0 0 -0.052"/>
      <inertia ixx="0.000479" ixy="0" ixz="0" iyy="0.000479" iyz="0" izz="0.0000563"/>
    </inertial>
  </link>
  <!-- 5. Forearm Rotation Joint (similar to right_forearm2forearmrot_joint) -->
  <joint name="right_forearm_rotation" type="revolute">
    <parent link="right_forearm_link"/>
    <child link="right_forearm_rotation_link"/>
    <origin rpy="0 0 0" xyz="0 0 -0.104"/>
    <axis xyz="0 0 1"/>
    <limit effort="30" lower="-1.57" upper="1.57" velocity="2.0"/>
    <dynamics damping="0.1" friction="0.1"/>
  </joint>
  <!-- TRANSMISSION for forearm_rotation -->
  <transmission name="trans_right_forearm_rotation">
    <joint name="right_forearm_rotation">
      <hardwareInterface>hardware_interface/PositionInterface</hardwareInterface>
    </joint>
    <actuator name="motor_e">
      <hardwareInterface>hardware_interface/PositionInterface</hardwareInterface>
      <mechanicalReduction>1</mechanicalReduction>
    </actuator>
  </transmission>
  <!-- 6. Wrist Pitch Link (similar to right_forearm_pitch_link) -->
  <link name="right_wrist_link">
    <visual>
      <geometry>
        <cylinder length="0.094" radius="0.015"/>
      </geometry>
      <origin rpy="0 0 0" xyz="0 0 -0.052"/>
      <material name="blue"/>
    </visual>
    <collision>
      <geometry>
        <cylinder length="0.03" radius="0.015"/>
      </geometry>
      <origin rpy="0 0 0" xyz="0 0 -0.052"/>
    </collision>
    <inertial>
      <mass value="0.3"/>
      <origin rpy="0 0 0" xyz="0 0 0"/>
      <inertia ixx="0.00001" ixy="0" ixz="0" iyy="0.00001" iyz="0" izz="0.00001"/>
    </inertial>
  </link>
  <!-- 6. Wrist Pitch Joint (similar to right_forearmrot2forearm_pitch_joint) -->
  <joint name="right_wrist_pitch" type="revolute">
    <parent link="right_forearm_rotation_link"/>
    <child link="right_wrist_link"/>
    <origin rpy="0 0 0" xyz="0 0 -0.104"/>
    <axis xyz="0 1 0"/>
    <limit effort="10" lower="-0.785" upper="0.785" velocity="2.0"/>
    <dynamics damping="0.1" friction="0.1"/>
  </joint>
  <!-- TRANSMISSION for wrist_pitch -->
  <transmission name="right_trans_wrist_pitch">
    <joint name="right_wrist_pitch">
      <hardwareInterface>hardware_interface/PositionInterface</hardwareInterface>
    </joint>
    <actuator name="motor_f">
      <hardwareInterface>hardware_interface/PositionInterface</hardwareInterface>
      <mechanicalReduction>1</mechanicalReduction>
    </actuator>
  </transmission>
  <!-- 7. Hand Link (similar to right_hand_link) -->
  <link name="right_hand_link">
    <visual>
      <geometry>
        <box size="0.04 0.02 0.12"/>
      </geometry>
      <origin rpy="0 0 0" xyz="0 0 -0.06"/>
      <material name="white"/>
    </visual>
    <collision>
      <geometry>
        <box size="0.04 0.02 0.12"/>
      </geometry>
      <origin rpy="0 0 0" xyz="0 0 -0.06"/>
    </collision>
    <inertial>
      <mass value="0.2"/>
      <origin rpy="0 0 0" xyz="0 0 -0.06"/>
      <inertia ixx="0.001" ixy="0" ixz="0" iyy="0.001" iyz="0" izz="0.001"/>
    </inertial>
  </link>
  <!-- 7. Wrist Yaw Joint (similar to right_forearm_roll2hand_joint but as a revolute joint) -->
  <joint name="right_wrist_yaw" type="revolute">
    <parent link="right_wrist_link"/>
    <child link="right_hand_link"/>
    <origin rpy="0 0 0" xyz="0 0 -0.094"/>
    <axis xyz="1 0 0"/>
    <!-- Z-axis rotation for yaw -->
    <limit effort="5" lower="-0.52" upper="0.52" velocity="2.0"/>
    <dynamics damping="0.05" friction="0.05"/>
  </joint>
  <!-- TRANSMISSION for wrist_yaw -->
  <transmission name="trans_right_wrist_yaw">
    <joint name="right_wrist_yaw">
      <hardwareInterface>hardware_interface/PositionInterface</hardwareInterface>
    </joint>
    <actuator name="motor_g">
      <hardwareInterface>hardware_interface/PositionInterface</hardwareInterface>
      <mechanicalReduction>1</mechanicalReduction>
    </actuator>
  </transmission>
  <!-- ros2_control tag -->
  <ros2_control name="GazeboSystem" type="system">
    <hardware>
      <plugin>gazebo_ros2_control/GazeboSystem</plugin>
    </hardware>
    <joint name="right_shoulder_pitch">
      <command_interface name="position">
        <param name="min">-2.51</param>
        <param name="max">2.51</param>
      </command_interface>
      <state_interface name="position"/>
      <state_interface name="velocity"/>
    </joint>
    <joint name="right_shoulder_roll">
      <command_interface name="position">
        <param name="min">-1.57</param>
        <param name="max">0.50</param>
      </command_interface>
      <state_interface name="position"/>
      <state_interface name="velocity"/>
    </joint>
    <joint name="right_upper_arm_rotation">
      <command_interface name="position">
        <param name="min">-1.57</param>
        <param name="max">1.57</param>
      </command_interface>
      <state_interface name="position"/>
      <state_interface name="velocity"/>
    </joint>
    <joint name="right_elbow_pitch">
      <command_interface name="position">
        <param name="min">-2.2</param>
        <param name="max">0</param>
      </command_interface>
      <state_interface name="position"/>
      <state_interface name="velocity"/>
    </joint>
    <joint name="right_forearm_rotation">
      <command_interface name="position">
        <param name="min">-1.57</param>
        <param name="max">1.57</param>
      </command_interface>
      <state_interface name="position"/>
      <state_interface name="velocity"/>
    </joint>
    <joint name="right_wrist_pitch">
      <command_interface name="position">
        <param name="min">-0.785</param>
        <param name="max">0.785</param>
      </command_interface>
      <state_interface name="position"/>
      <state_interface name="velocity"/>
    </joint>
    <joint name="right_wrist_yaw">
      <command_interface name="position">
        <param name="min">-0.52</param>
        <param name="max">0.52</param>
      </command_interface>
      <state_interface name="position"/>
      <state_interface name="velocity"/>
    </joint>
  </ros2_control>
  <gazebo>
    <plugin filename="libgazebo_ros2_control.so" name="gazebo_ros2_control">
      <parameters>/home/trob/vm/humarm/install/right_arm/share/right_arm/config/ros2_control.yaml</parameters>
    </plugin>
  </gazebo>
</robot>
